Workbook

Sheet Budget
A1: Colonne 1 | B1: Septembre 2026 | C1: Aout 2026 | D1: Juillet 2026 | E1: Juin 2026 | F1: Mai 2026 | G1: Avril 2026 | H1: Mars 2026 | I1: Fevrier 2026 | J1: Janvier 2026 | K1: Décembre 2025 | L1: Novembre 2025 | M1: Octobre 2025 | N1: Septembre 2025 | O1: Aout 2025 | P1: Juillet 2025 | Q1: Juin 2025 | R1: Mai 2025 | S1: Avril 2025 | T1: Mars 2025 | U1: Fevrier 2025 | V1: Janvier 2025
A2: Courses | B2: =SUMIF('Septembre 2026'!$K$3:$K$243,$A2,'Septembre 2026'!$H$3:$H$243) -> 254.23 | C2: =SUMIF('Aout 2026'!$K$3:$K$243,$A2,'Aout 2026'!$H$3:$H$243) -> 2120.04 | D2: =SUMIF('Juillet 2026'!$K$3:$K$241,$A2,'Juillet 2026'!$H$3:$H$241) -> 1639.04 | E2: =SUMIF('Juin 2026'!$K$3:$K$241,$A2,'Juin 2026'!$H$3:$H$241) -> 1872.28 | F2: =SUMIF('Mai 2026'!$K$3:$K$241,$A2,'Mai 2026'!$H$3:$H$241) -> 2139.03 | G2: =SUMIF('Avril 2026'!$K$3:$K$241,$A2,'Avril 2026'!$H$3:$H$241) -> 1775.59 | H2: =SUMIF('Mars 2026'!$K$3:$K$241,$A2,'Mars 2026'!$H$3:$H$241) -> 1241.27 | I2: =SUMIF('Fevrier 2026'!$K$3:$K$241,$A2,'Fevrier 2026'!$H$3:$H$241) -> 1544.09 | J2: =SUMIF('Janvier 2026'!$K$3:$K$241,$A2,'Janvier 2026'!$H$3:$H$241) -> 1114.46 | K2: =SUMIF(#REF!,$A2,#REF!) -> #REF! | L2: =SUMIF(#REF!,$A2,#REF!) -> #REF! | M2: =SUMIF(#REF!,$A2,#REF!) -> #REF! | N2: =SUMIF(#REF!,$A2,#REF!) -> #REF! | O2: =SUMIF(#REF!,$A2,#REF!) -> #REF! | P2: =SUMIF(#REF!,$A2,#REF!) -> #REF! | Q2: =SUMIF(#REF!,$A2,#REF!) -> #REF! | R2: =SUMIF(#REF!,$A2,#REF!) -> #REF! | ... V2: =SUMIF(#REF!,$A2,#REF!) -> #REF!
A3: Logement | B3: =SUMIF('Septembre 2026'!$K$3:$K$243,$A3,'Septembre 2026'!$H$3:$H$243) -> 2582.27 | C3: =SUMIF('Aout 2026'!$K$3:$K$243,$A3,'Aout 2026'!$H$3:$H$243) -> 2842.23 | D3: =SUMIF('Juillet 2026'!$K$3:$K$241,$A3,'Juillet 2026'!$H$3:$H$241) -> 3006.77 | E3: =SUMIF('Juin 2026'!$K$3:$K$241,$A3,'Juin 2026'!$H$3:$H$241) -> 2847.2 | F3: =SUMIF('Mai 2026'!$K$3:$K$241,$A3,'Mai 2026'!$H$3:$H$241) -> 2932.63 | G3: =SUMIF('Avril 2026'!$K$3:$K$241,$A3,'Avril 2026'!$H$3:$H$241) -> 2949.2 | H3: =SUMIF('Mars 2026'!$K$3:$K$241,$A3,'Mars 2026'!$H$3:$H$241) -> 2907.37 | I3: =SUMIF('Fevrier 2026'!$K$3:$K$241,$A3,'Fevrier 2026'!$H$3:$H$241) -> 2805.43 | J3: =SUMIF('Janvier 2026'!$K$3:$K$241,$A3,'Janvier 2026'!$H$3:$H$241) -> 2899.11 | K3: =SUMIF(#REF!,$A3,#REF!) -> #REF! | L3: =SUMIF(#REF!,$A3,#REF!) -> #REF! | M3: =SUMIF(#REF!,$A3,#REF!) -> #REF! | N3: =SUMIF(#REF!,$A3,#REF!) -> #REF! | O3: =SUMIF(#REF!,$A3,#REF!) -> #REF! | P3: =SUMIF(#REF!,$A3,#REF!) -> #REF! | Q3: =SUMIF(#REF!,$A3,#REF!) -> #REF! | R3: =SUMIF(#REF!,$A3,#REF!) -> #REF! | ... V3: =SUMIF(#REF!,$A3,#REF!) -> #REF!
A4: Charges | B4: =SUMIF('Septembre 2026'!$K$3:$K$243,$A4,'Septembre 2026'!$H$3:$H$243) -> 221.32 | C4: =SUMIF('Aout 2026'!$K$3:$K$243,$A4,'Aout 2026'!$H$3:$H$243) -> 400.44 | D4: =SUMIF('Juillet 2026'!$K$3:$K$241,$A4,'Juillet 2026'!$H$3:$H$241) -> 1183.78 | E4: =SUMIF('Juin 2026'!$K$3:$K$241,$A4,'Juin 2026'!$H$3:$H$241) -> 637.86 | F4: =SUMIF('Mai 2026'!$K$3:$K$241,$A4,'Mai 2026'!$H$3:$H$241) -> 905.12 | G4: =SUMIF('Avril 2026'!$K$3:$K$241,$A4,'Avril 2026'!$H$3:$H$241) -> 585.68 | H4: =SUMIF('Mars 2026'!$K$3:$K$241,$A4,'Mars 2026'!$H$3:$H$241) -> 561.59 | I4: =SUMIF('Fevrier 2026'!$K$3:$K$241,$A4,'Fevrier 2026'!$H$3:$H$241) -> 724.03 | J4: =SUMIF('Janvier 2026'!$K$3:$K$241,$A4,'Janvier 2026'!$H$3:$H$241) -> 1632.2 | K4: =SUMIF(#REF!,$A4,#REF!) -> #REF! | L4: =SUMIF(#REF!,$A4,#REF!) -> #REF! | M4: =SUMIF(#REF!,$A4,#REF!) -> #REF! | N4: =SUMIF(#REF!,$A4,#REF!) -> #REF! | O4: =SUMIF(#REF!,$A4,#REF!) -> #REF! | P4: =SUMIF(#REF!,$A4,#REF!) -> #REF! | Q4: =SUMIF(#REF!,$A4,#REF!) -> #REF! | R4: =SUMIF(#REF!,$A4,#REF!) -> #REF! | ... V4: =SUMIF(#REF!,$A4,#REF!) -> #REF!
A5: Internet/Téléphone | B5: =SUMIF('Septembre 2026'!$K$3:$K$243,$A5,'Septembre 2026'!$H$3:$H$243) -> 0.99 | C5: =SUMIF('Aout 2026'!$K$3:$K$243,$A5,'Aout 2026'!$H$3:$H$243) -> 132.89 | D5: =SUMIF('Juillet 2026'!$K$3:$K$241,$A5,'Juillet 2026'!$H$3:$H$241) -> 113.91 | E5: =SUMIF('Juin 2026'!$K$3:$K$241,$A5,'Juin 2026'!$H$3:$H$241) -> 162.8 | F5: =SUMIF('Mai 2026'!$K$3:$K$241,$A5,'Mai 2026'!$H$3:$H$241) -> 169.14 | G5: =SUMIF('Avril 2026'!$K$3:$K$241,$A5,'Avril 2026'!$H$3:$H$241) -> 123.9 | H5: =SUMIF('Mars 2026'!$K$3:$K$241,$A5,'Mars 2026'!$H$3:$H$241) -> 137.89 | I5: =SUMIF('Fevrier 2026'!$K$3:$K$241,$A5,'Fevrier 2026'!$H$3:$H$241) -> 183.92 | J5: =SUMIF('Janvier 2026'!$K$3:$K$241,$A5,'Janvier 2026'!$H$3:$H$241) -> 752.48 | K5: =SUMIF(#REF!,$A5,#REF!) -> #REF! | L5: =SUMIF(#REF!,$A5,#REF!) -> #REF! | M5: =SUMIF(#REF!,$A5,#REF!) -> #REF! | N5: =SUMIF(#REF!,$A5,#REF!) -> #REF! | O5: =SUMIF(#REF!,$A5,#REF!) -> #REF! | P5: =SUMIF(#REF!,$A5,#REF!) -> #REF! | Q5: =SUMIF(#REF!,$A5,#REF!) -> #REF! | R5: =SUMIF(#REF!,$A5,#REF!) -> #REF! | ... V5: =SUMIF(#REF!,$A5,#REF!) -> #REF!
A6: Assurances/Mutuelle | B6: =SUMIF('Septembre 2026'!$K$3:$K$243,$A6,'Septembre 2026'!$H$3:$H$243) -> 0 | C6: =SUMIF('Aout 2026'!$K$3:$K$243,$A6,'Aout 2026'!$H$3:$H$243) -> 274.88 | D6: =SUMIF('Juillet 2026'!$K$3:$K$241,$A6,'Juillet 2026'!$H$3:$H$241) -> 274.88 | E6: =SUMIF('Juin 2026'!$K$3:$K$241,$A6,'Juin 2026'!$H$3:$H$241) -> 255.89 | F6: =SUMIF('Mai 2026'!$K$3:$K$241,$A6,'Mai 2026'!$H$3:$H$241) -> 269.31 | G6: =SUMIF('Avril 2026'!$K$3:$K$241,$A6,'Avril 2026'!$H$3:$H$241) -> 356.17 | H6: =SUMIF('Mars 2026'!$K$3:$K$241,$A6,'Mars 2026'!$H$3:$H$241) -> 328.74 | I6: =SUMIF('Fevrier 2026'!$K$3:$K$241,$A6,'Fevrier 2026'!$H$3:$H$241) -> 328.74 | J6: =SUMIF('Janvier 2026'!$K$3:$K$241,$A6,'Janvier 2026'!$H$3:$H$241) -> 281 | K6: =SUMIF(#REF!,$A6,#REF!) -> #REF! | L6: =SUMIF(#REF!,$A6,#REF!) -> #REF! | M6: =SUMIF(#REF!,$A6,#REF!) -> #REF! | N6: =SUMIF(#REF!,$A6,#REF!) -> #REF! | O6: =SUMIF(#REF!,$A6,#REF!) -> #REF! | P6: =SUMIF(#REF!,$A6,#REF!) -> #REF! | Q6: =SUMIF(#REF!,$A6,#REF!) -> #REF! | R6: =SUMIF(#REF!,$A6,#REF!) -> #REF! | ... V6: =SUMIF(#REF!,$A6,#REF!) -> #REF!
A7: Voiture/Déplacement | B7: =SUMIF('Septembre 2026'!$K$3:$K$243,$A7,'Septembre 2026'!$H$3:$H$243) -> 0 | C7: =SUMIF('Aout 2026'!$K$3:$K$243,$A7,'Aout 2026'!$H$3:$H$243) -> 516.41 | D7: =SUMIF('Juillet 2026'!$K$3:$K$241,$A7,'Juillet 2026'!$H$3:$H$241) -> 485.89 | E7: =SUMIF('Juin 2026'!$K$3:$K$241,$A7,'Juin 2026'!$H$3:$H$241) -> 600.4 | F7: =SUMIF('Mai 2026'!$K$3:$K$241,$A7,'Mai 2026'!$H$3:$H$241) -> 512.85 | G7: =SUMIF('Avril 2026'!$K$3:$K$241,$A7,'Avril 2026'!$H$3:$H$241) -> 428.15 | H7: =SUMIF('Mars 2026'!$K$3:$K$241,$A7,'Mars 2026'!$H$3:$H$241) -> 742.95 | I7: =SUMIF('Fevrier 2026'!$K$3:$K$241,$A7,'Fevrier 2026'!$H$3:$H$241) -> 443.85 | J7: =SUMIF('Janvier 2026'!$K$3:$K$241,$A7,'Janvier 2026'!$H$3:$H$241) -> 600.11 | K7: =SUMIF(#REF!,$A7,#REF!) -> #REF! | L7: =SUMIF(#REF!,$A7,#REF!) -> #REF! | M7: =SUMIF(#REF!,$A7,#REF!) -> #REF! | N7: =SUMIF(#REF!,$A7,#REF!) -> #REF! | O7: =SUMIF(#REF!,$A7,#REF!) -> #REF! | P7: =SUMIF(#REF!,$A7,#REF!) -> #REF! | Q7: =SUMIF(#REF!,$A7,#REF!) -> #REF! | R7: =SUMIF(#REF!,$A7,#REF!) -> #REF! | ... V7: =SUMIF(#REF!,$A7,#REF!) -> #REF!
A8: Scolarité | B8: =SUMIF('Septembre 2026'!$K$3:$K$243,$A8,'Septembre 2026'!$H$3:$H$243) -> 118.97 | C8: =SUMIF('Aout 2026'!$K$3:$K$243,$A8,'Aout 2026'!$H$3:$H$243) -> 414.32 | D8: =SUMIF('Juillet 2026'!$K$3:$K$241,$A8,'Juillet 2026'!$H$3:$H$241) -> 816.3 | E8: =SUMIF('Juin 2026'!$K$3:$K$241,$A8,'Juin 2026'!$H$3:$H$241) -> 196.9 | F8: =SUMIF('Mai 2026'!$K$3:$K$241,$A8,'Mai 2026'!$H$3:$H$241) -> 278.3 | G8: =SUMIF('Avril 2026'!$K$3:$K$241,$A8,'Avril 2026'!$H$3:$H$241) -> 178.3 | H8: =SUMIF('Mars 2026'!$K$3:$K$241,$A8,'Mars 2026'!$H$3:$H$241) -> 220.18 | I8: =SUMIF('Fevrier 2026'!$K$3:$K$241,$A8,'Fevrier 2026'!$H$3:$H$241) -> 172.1 | J8: =SUMIF('Janvier 2026'!$K$3:$K$241,$A8,'Janvier 2026'!$H$3:$H$241) -> 178.3 | K8: =SUMIF(#REF!,$A8,#REF!) -> #REF! | L8: =SUMIF(#REF!,$A8,#REF!) -> #REF! | M8: =SUMIF(#REF!,$A8,#REF!) -> #REF! | N8: =SUMIF(#REF!,$A8,#REF!) -> #REF! | O8: =SUMIF(#REF!,$A8,#REF!) -> #REF! | P8: =SUMIF(#REF!,$A8,#REF!) -> #REF! | Q8: =SUMIF(#REF!,$A8,#REF!) -> #REF! | R8: =SUMIF(#REF!,$A8,#REF!) -> #REF! | ... V8: =SUMIF(#REF!,$A8,#REF!) -> #REF!
A9: Vêtements | B9: =SUMIF('Septembre 2026'!$K$3:$K$243,$A9,'Septembre 2026'!$H$3:$H$243) -> 69.08 | C9: =SUMIF('Aout 2026'!$K$3:$K$243,$A9,'Aout 2026'!$H$3:$H$243) -> 375.16 | D9: =SUMIF('Juillet 2026'!$K$3:$K$241,$A9,'Juillet 2026'!$H$3:$H$241) -> 570.47 | E9: =SUMIF('Juin 2026'!$K$3:$K$241,$A9,'Juin 2026'!$H$3:$H$241) -> 311.51 | F9: =SUMIF('Mai 2026'!$K$3:$K$241,$A9,'Mai 2026'!$H$3:$H$241) -> 150.66 | G9: =SUMIF('Avril 2026'!$K$3:$K$241,$A9,'Avril 2026'!$H$3:$H$241) -> 226.77 | H9: =SUMIF('Mars 2026'!$K$3:$K$241,$A9,'Mars 2026'!$H$3:$H$241) -> 274.9 | I9: =SUMIF('Fevrier 2026'!$K$3:$K$241,$A9,'Fevrier 2026'!$H$3:$H$241) -> 229.95 | J9: =SUMIF('Janvier 2026'!$K$3:$K$241,$A9,'Janvier 2026'!$H$3:$H$241) -> 85 | K9: =SUMIF(#REF!,$A9,#REF!) -> #REF! | L9: =SUMIF(#REF!,$A9,#REF!) -> #REF! | M9: =SUMIF(#REF!,$A9,#REF!) -> #REF! | N9: =SUMIF(#REF!,$A9,#REF!) -> #REF! | O9: =SUMIF(#REF!,$A9,#REF!) -> #REF! | P9: =SUMIF(#REF!,$A9,#REF!) -> #REF! | Q9: =SUMIF(#REF!,$A9,#REF!) -> #REF! | R9: =SUMIF(#REF!,$A9,#REF!) -> #REF! | ... V9: =SUMIF(#REF!,$A9,#REF!) -> #REF!
A10: Bricolage/Travaux | B10: =SUMIF('Septembre 2026'!$K$3:$K$243,$A10,'Septembre 2026'!$H$3:$H$243) -> 62.92 | C10: =SUMIF('Aout 2026'!$K$3:$K$243,$A10,'Aout 2026'!$H$3:$H$243) -> 1467.81 | D10: =SUMIF('Juillet 2026'!$K$3:$K$241,$A10,'Juillet 2026'!$H$3:$H$241) -> 1051.41 | E10: =SUMIF('Juin 2026'!$K$3:$K$241,$A10,'Juin 2026'!$H$3:$H$241) -> 330.75 | F10: =SUMIF('Mai 2026'!$K$3:$K$241,$A10,'Mai 2026'!$H$3:$H$241) -> 402.83 | G10: =SUMIF('Avril 2026'!$K$3:$K$241,$A10,'Avril 2026'!$H$3:$H$241) -> 418.51 | H10: =SUMIF('Mars 2026'!$K$3:$K$241,$A10,'Mars 2026'!$H$3:$H$241) -> 988.72 | I10: =SUMIF('Fevrier 2026'!$K$3:$K$241,$A10,'Fevrier 2026'!$H$3:$H$241) -> 118.29 | J10: =SUMIF('Janvier 2026'!$K$3:$K$241,$A10,'Janvier 2026'!$H$3:$H$241) -> 748.33 | K10: =SUMIF(#REF!,$A10,#REF!) -> #REF! | L10: =SUMIF(#REF!,$A10,#REF!) -> #REF! | M10: =SUMIF(#REF!,$A10,#REF!) -> #REF! | N10: =SUMIF(#REF!,$A10,#REF!) -> #REF! | O10: =SUMIF(#REF!,$A10,#REF!) -> #REF! | P10: =SUMIF(#REF!,$A10,#REF!) -> #REF! | Q10: =SUMIF(#REF!,$A10,#REF!) -> #REF! | R10: =SUMIF(#REF!,$A10,#REF!) -> #REF! | ... V10: =SUMIF(#REF!,$A10,#REF!) -> #REF!
A11: Loisirs | B11: =SUMIF('Septembre 2026'!$K$3:$K$243,$A11,'Septembre 2026'!$H$3:$H$243) -> 0 | C11: =SUMIF('Aout 2026'!$K$3:$K$243,$A11,'Aout 2026'!$H$3:$H$243) -> 1159.87 | D11: =SUMIF('Juillet 2026'!$K$3:$K$241,$A11,'Juillet 2026'!$H$3:$H$241) -> 626.8 | E11: =SUMIF('Juin 2026'!$K$3:$K$241,$A11,'Juin 2026'!$H$3:$H$241) -> 331.86 | F11: =SUMIF('Mai 2026'!$K$3:$K$241,$A11,'Mai 2026'!$H$3:$H$241) -> 176.04 | G11: =SUMIF('Avril 2026'!$K$3:$K$241,$A11,'Avril 2026'!$H$3:$H$241) -> 351.58 | H11: =SUMIF('Mars 2026'!$K$3:$K$241,$A11,'Mars 2026'!$H$3:$H$241) -> 433.49 | I11: =SUMIF('Fevrier 2026'!$K$3:$K$241,$A11,'Fevrier 2026'!$H$3:$H$241) -> 673.55 | J11: =SUMIF('Janvier 2026'!$K$3:$K$241,$A11,'Janvier 2026'!$H$3:$H$241) -> 109.17 | K11: =SUMIF(#REF!,$A11,#REF!) -> #REF! | L11: =SUMIF(#REF!,$A11,#REF!) -> #REF! | M11: =SUMIF(#REF!,$A11,#REF!) -> #REF! | N11: =SUMIF(#REF!,$A11,#REF!) -> #REF! | O11: =SUMIF(#REF!,$A11,#REF!) -> #REF! | P11: =SUMIF(#REF!,$A11,#REF!) -> #REF! | Q11: =SUMIF(#REF!,$A11,#REF!) -> #REF! | R11: =SUMIF(#REF!,$A11,#REF!) -> #REF! | ... V11: =SUMIF(#REF!,$A11,#REF!) -> #REF!
A12: Divers | B12: =SUMIF('Septembre 2026'!$K$3:$K$243,$A12,'Septembre 2026'!$H$3:$H$243) -> 73.69 | C12: =SUMIF('Aout 2026'!$K$3:$K$243,$A12,'Aout 2026'!$H$3:$H$243) -> 983.25 | D12: =SUMIF('Juillet 2026'!$K$3:$K$241,$A12,'Juillet 2026'!$H$3:$H$241) -> 314.19 | E12: =SUMIF('Juin 2026'!$K$3:$K$241,$A12,'Juin 2026'!$H$3:$H$241) -> 313.62 | F12: =SUMIF('Mai 2026'!$K$3:$K$241,$A12,'Mai 2026'!$H$3:$H$241) -> 673.22 | G12: =SUMIF('Avril 2026'!$K$3:$K$241,$A12,'Avril 2026'!$H$3:$H$241) -> 698.32 | H12: =SUMIF('Mars 2026'!$K$3:$K$241,$A12,'Mars 2026'!$H$3:$H$241) -> 144.51 | I12: =SUMIF('Fevrier 2026'!$K$3:$K$241,$A12,'Fevrier 2026'!$H$3:$H$241) -> 430.68 | J12: =SUMIF('Janvier 2026'!$K$3:$K$241,$A12,'Janvier 2026'!$H$3:$H$241) -> 103.22 | K12: =SUMIF(#REF!,$A12,#REF!) -> #REF! | L12: =SUMIF(#REF!,$A12,#REF!) -> #REF! | M12: =SUMIF(#REF!,$A12,#REF!) -> #REF! | N12: =SUMIF(#REF!,$A12,#REF!) -> #REF! | O12: =SUMIF(#REF!,$A12,#REF!) -> #REF! | P12: =SUMIF(#REF!,$A12,#REF!) -> #REF! | Q12: =SUMIF(#REF!,$A12,#REF!) -> #REF! | R12: =SUMIF(#REF!,$A12,#REF!) -> #REF! | ... V12: =SUMIF(#REF!,$A12,#REF!) -> #REF!
A13: Medical | B13: =SUMIF('Septembre 2026'!$K$3:$K$243,$A13,'Septembre 2026'!$H$3:$H$243) -> 38.2 | C13: =SUMIF('Aout 2026'!$K$3:$K$243,$A13,'Aout 2026'!$H$3:$H$243) -> 465.55 | D13: =SUMIF('Juillet 2026'!$K$3:$K$241,$A13,'Juillet 2026'!$H$3:$H$241) -> 119.3 | E13: =SUMIF('Juin 2026'!$K$3:$K$241,$A13,'Juin 2026'!$H$3:$H$241) -> 53.25 | F13: =SUMIF('Mai 2026'!$K$3:$K$241,$A13,'Mai 2026'!$H$3:$H$241) -> 178.48 | G13: =SUMIF('Avril 2026'!$K$3:$K$241,$A13,'Avril 2026'!$H$3:$H$241) -> 0 | H13: =SUMIF('Mars 2026'!$K$3:$K$241,$A13,'Mars 2026'!$H$3:$H$241) -> 178.29 | I13: =SUMIF('Fevrier 2026'!$K$3:$K$241,$A13,'Fevrier 2026'!$H$3:$H$241) -> 117.78 | J13: =SUMIF('Janvier 2026'!$K$3:$K$241,$A13,'Janvier 2026'!$H$3:$H$241) -> 481.7 | K13: =SUMIF(#REF!,$A13,#REF!) -> #REF! | L13: =SUMIF(#REF!,$A13,#REF!) -> #REF! | M13: =SUMIF(#REF!,$A13,#REF!) -> #REF! | N13: =SUMIF(#REF!,$A13,#REF!) -> #REF! | O13: =SUMIF(#REF!,$A13,#REF!) -> #REF! | P13: =SUMIF(#REF!,$A13,#REF!) -> #REF! | Q13: =SUMIF(#REF!,$A13,#REF!) -> #REF! | R13: =SUMIF(#REF!,$A13,#REF!) -> #REF! | ... V13: =SUMIF(#REF!,$A13,#REF!) -> #REF!
... A16: Cadeau | B16: =SUMIF('Septembre 2026'!$K$3:$K$243,$A16,'Septembre 2026'!$H$3:$H$243) -> 0 | C16: =SUMIF('Aout 2026'!$K$3:$K$243,$A16,'Aout 2026'!$H$3:$H$243) -> 0 | D16: =SUMIF('Juillet 2026'!$K$3:$K$241,$A16,'Juillet 2026'!$H$3:$H$241) -> 0 | E16: =SUMIF('Juin 2026'!$K$3:$K$241,$A16,'Juin 2026'!$H$3:$H$241) -> 88.69 | F16: =SUMIF('Mai 2026'!$K$3:$K$241,$A16,'Mai 2026'!$H$3:$H$241) -> 197.89 | G16: =SUMIF('Avril 2026'!$K$3:$K$241,$A16,'Avril 2026'!$H$3:$H$241) -> 166.99 | H16: =SUMIF('Mars 2026'!$K$3:$K$241,$A16,'Mars 2026'!$H$3:$H$241) -> 183.8 | I16: =SUMIF('Fevrier 2026'!$K$3:$K$241,$A16,'Fevrier 2026'!$H$3:$H$241) -> 290 | J16: =SUMIF('Janvier 2026'!$K$3:$K$241,$A16,'Janvier 2026'!$H$3:$H$241) -> 469.35 | K16: =SUMIF(#REF!,$A16,#REF!) -> #REF! | L16: =SUMIF(#REF!,$A16,#REF!) -> #REF! | M16: =SUMIF(#REF!,$A16,#REF!) -> #REF! | N16: =SUMIF(#REF!,$A16,#REF!) -> #REF! | O16: =SUMIF(#REF!,$A16,#REF!) -> #REF! | P16: =SUMIF(#REF!,$A16,#REF!) -> #REF! | Q16: =SUMIF(#REF!,$A16,#REF!) -> #REF! | R16: =SUMIF(#REF!,$A16,#REF!) -> #REF! | ... V16: =SUMIF(#REF!,$A16,#REF!) -> #REF!
A17: Total | B17: =SUM(B2:B14) -> 3421.67 | C17: =SUM(C2:C14) -> 11152.85 | D17: =SUM(D2:D14) -> 10202.74 | E17: =SUM(E2:E14) -> 7984.32 | F17: =SUM(F2:F14) -> 8976.51 | G17: =SUM(G2:G14) -> 8313.81 | H17: =SUM(H2:H14) -> 8183 | I17: =SUM(I2:I14) -> 7834.87 | ... V17: =SUM(V2:V14) -> #REF!
A18: Bilan Fin de mois | B18: =INDIRECT(B1&"!D43")-INDIRECT(B1&"!C39") -> #REF! | C18: =INDIRECT(C1&"!D43")-INDIRECT(C1&"!C39") -> #REF! | D18: =INDIRECT(D1&"!D43")-INDIRECT(D1&"!C39") -> #REF! | E18: =INDIRECT(E1&"!D43")-INDIRECT(E1&"!C39") -> #REF! | F18: =INDIRECT(F1&"!D43")-INDIRECT(F1&"!C39") -> #REF! | G18: =INDIRECT(G1&"!D43")-INDIRECT(G1&"!C39") -> #REF! | H18: =INDIRECT(H1&"!D43")-INDIRECT(H1&"!C39") -> #REF! | I18: =INDIRECT(I1&"!D43")-INDIRECT(I1&"!C39") -> #REF! | ... V18: =INDIRECT(V1&"!D43")-INDIRECT(V1&"!C39") -> #REF!

Sheet Septembre 2026
B1: Recettes | E1: Dépenses | K1: Cadeau
B3: Salaire Pierre | C3: 5226.16 | E3: Loyer Elouen | F3: 669.7 | G3: x | H3: =IF(G3="x",F3,0) -> 669.7 | K3: Logement
B4: Salaire Sterenn | C4: 2086.77 | E4: Argent de poche Elouen | H4: =IF(G4="x",F4,0) -> 0 | K4: Charges
B5: CAF | E5: Engie Elouen | F5: 66.32 | G5: x | H5: =IF(G5="x",F5,0) -> 66.32 | K5: Charges
E6: Argent de poche Arthur | F6: 155 | G6: x | H6: =IF(G6="x",F6,0) -> 155 | K6: Charges
E7: Prêt 25 | F7: 995.15 | G7: x | H7: =IF(G7="x",F7,0) -> 995.15 | K7: Logement
B8: Note de frais Igienair | C8: 160.89 | E8: Prêt 15 | F8: 883.42 | G8: x | H8: =IF(G8="x",F8,0) -> 883.42 | K8: Logement
B9: Remboursement Padel Edouard | C9: 4 | E9: Assurances prêt | F9: 11.46 | H9: =IF(G9="x",F9,0) -> 0 | K9: Logement
E10: Assurances prêt | F10: 32.57 | H10: =IF(G10="x",F10,0) -> 0 | K10: Logement
E11: Assurances prêt | F11: 79.98 | H11: =IF(G11="x",F11,0) -> 0 | K11: Logement
E12: Assurances prêt | F12: 28.49 | H12: =IF(G12="x",F12,0) -> 0 | K12: Logement
E13: Disney | F13: 6.99 | H13: =IF(G13="x",F13,0) -> 0 | K13: Internet/Téléphone
E14: EDF Arthur | F14: 65 | H14: =IF(G14="x",F14,0) -> 0 | K14: Charges
E15: EkWateur | F15: 208 | H15: =IF(G15="x",F15,0) -> 0 | K15: Charges
E16: Sosh Maison | F16: 24.99 | H16: =IF(G16="x",F16,0) -> 0 | K16: Internet/Téléphone
H17: =IF(G17="x",F17,0) -> 0 | K17: Internet/Téléphone
E18: Sosh Ael | F18: 14.99 | H18: =IF(G18="x",F18,0) -> 0 | K18: Internet/Téléphone
E19: Sosh Elouen | F19: 14.99 | H19: =IF(G19="x",F19,0) -> 0 | K19: Internet/Téléphone
E20: Sosh Sterenn | F20: 10.99 | H20: =IF(G20="x",F20,0) -> 0 | K20: Internet/Téléphone
E21: Mutuelle | F21: 104.98 | H21: =IF(G21="x",F21,0) -> 0 | K21: Assurances/Mutuelle
E23: AxaHabitation | F23: 62.88 | H23: =IF(G23="x",F23,0) -> 0 | K23: Assurances/Mutuelle
E24: VW LLD | F24: 331.65 | H24: =IF(G24="x",F24,0) -> 0 | K24: Voiture/Déplacement
E25: Axa Voiture | F25: 88.03 | H25: =IF(G25="x",F25,0) -> 0 | K25: Assurances/Mutuelle
E26: Suravenir Garanties Vie | F26: 18.99 | H26: =IF(G26="x",F26,0) -> 0 | K26: Assurances/Mutuelle
E27: Joséphine | F27: 20 | G27: x | H27: =IF(G27="x",F27,0) -> 20 | K27: Divers
E28: Canal Plus | F28: 21.99 | H28: =IF(G28="x",F28,0) -> 0 | K28: Internet/Téléphone
H29: =IF(G29="x",F29,0) -> 0 | K29: Voiture/Déplacement
E30: Keolis Elouen | F30: 21.4 | H30: =IF(G30="x",F30,0) -> 0 | K30: Voiture/Déplacement
E31: Apple | F31: 0.99 | H31: =IF(G31="x",F31,0) -> 0 | K31: Internet/Téléphone
E32: Apple | F32: 0.99 | G32: x | H32: =IF(G32="x",F32,0) -> 0.99 | K32: Internet/Téléphone
E33: Apple | F33: 16.99 | H33: =IF(G33="x",F33,0) -> 0 | K33: Internet/Téléphone
E34: Lycée | F34: 450 | H34: =IF(G34="x",F34,0) -> 0 | K34: Scolarité
E35: Ménage | F35: 170 | H35: =IF(G35="x",F35,0) -> 0 | K35: Logement
E36: Urssaaf | F36: 34 | G36: x | H36: =IF(G36="x",F36,0) -> 34 | K36: Logement
E37: Cotisation Eurocompte | F37: 19.03 | H37: =IF(G37="x",F37,0) -> 0 | K37: Charges
E38: Indivision | F38: 33.89 | H38: =IF(G38="x",F38,0) -> 0 | K38: Charges
A39: Etat mois précédent | C39: ='Aout 2026'!D43 -> #REF!
A40: Recettes fixes | C40: =SUM(C2:C6) -> 7312.93 | E40: Somme dépenses prévues | F40: =SUM(F2:F38) -> 4663.85 | G40: Somme dépenses réelles | H40: =SUM(H2:H38) -> 2824.58 | I40: Delta moins les exceptions
A41: Recettes additionnelles du mois | C41: =SUM(C8:C35) -> 164.89 | E41: Reste previsionnel | F41: =C42-F40 -> #REF! | G41: Delta du mois | H41: =C39+C40+C41-H40-F42 -> #REF!
A42: Total Recettes | C42: =SUM(C39:C41) -> #REF! | E42: Somme dépenses non prévues | F42: =SUM(J44:J247) -> 597.09
...

Sheet Aout 2026
B1: Recettes | E1: Dépenses | K1: Cadeau
B3: Salaire Pierre | C3: 5393.99 | E3: Loyer Elouen | F3: 669.7 | G3: x | H3: =IF(G3="x",F3,0) -> 669.7 | K3: Logement
B4: Salaire Sterenn | C4: 1828.73 | E4: Argent de poche Elouen | H4: =IF(G4="x",F4,0) -> 0 | K4: Charges
B5: CAF | C5: 114.19 | E5: Engie Elouen | F5: 70 | G5: x | H5: =IF(G5="x",F5,0) -> 70 | K5: Charges
E6: Argent de poche Arthur | F6: 14.99 | G6: x | H6: =IF(G6="x",F6,0) -> 14.99 | K6: Charges
E7: Prêt 25 | F7: 995.15 | G7: x | H7: =IF(G7="x",F7,0) -> 995.15 | K7: Logement
E8: Prêt 15 | F8: 883.42 | G8: x | H8: =IF(G8="x",F8,0) -> 883.42 | K8: Logement
B9: Remboursement Leroy | C9: 27.06 | E9: Assurances prêt | F9: 11.46 | G9: x | H9: =IF(G9="x",F9,0) -> 11.46 | K9: Logement
B10: Epargne Travaux | C10: 742 | E10: Assurances prêt | F10: 32.57 | G10: x | H10: =IF(G10="x",F10,0) -> 32.57 | K10: Logement
B11: Epargne Travaux | C11: 520 | E11: Assurances prêt | F11: 79.98 | G11: x | H11: =IF(G11="x",F11,0) -> 79.98 | K11: Logement
B12: Remboursement Axa | C12: 264.09 | E12: Assurances prêt | F12: 28.49 | G12: x | H12: =IF(G12="x",F12,0) -> 28.49 | K12: Logement
B13: Remboursement Notaire | C13: 789.8 | E13: Disney | F13: 6.99 | G13: x | H13: =IF(G13="x",F13,0) -> 6.99 | K13: Internet/Téléphone
B14: Epargne Compresseur | C14: 523.7 | E14: EDF Arthur | F14: 65 | H14: =IF(G14="x",F14,0) -> 0 | K14: Charges
B15: Scolarité Pret Arthur | C15: 726.96 | E15: EkWateur | F15: 208 | G15: x | H15: =IF(G15="x",F15,0) -> 208 | K15: Charges
E16: Sosh Maison | F16: 24.99 | G16: x | H16: =IF(G16="x",F16,0) -> 24.99 | K16: Internet/Téléphone
H17: =IF(G17="x",F17,0) -> 0 | K17: Internet/Téléphone
E18: Sosh Ael | F18: 14.99 | G18: x | H18: =IF(G18="x",F18,0) -> 14.99 | K18: Internet/Téléphone
E19: Sosh Elouen | F19: 14.99 | G19: x | H19: =IF(G19="x",F19,0) -> 14.99 | K19: Internet/Téléphone
E20: Sosh Sterenn | F20: 10.99 | G20: x | H20: =IF(G20="x",F20,0) -> 10.99 | K20: Internet/Téléphone
E21: Mutuelle | F21: 104.98 | G21: x | H21: =IF(G21="x",F21,0) -> 104.98 | K21: Assurances/Mutuelle
E23: AxaHabitation | F23: 62.88 | G23: x | H23: =IF(G23="x",F23,0) -> 62.88 | K23: Assurances/Mutuelle
E24: VW LDD | F24: 331.65 | G24: x | H24: =IF(G24="x",F24,0) -> 331.65 | K24: Voiture/Déplacement
E25: Axa Voiture | F25: 88.03 | G25: x | H25: =IF(G25="x",F25,0) -> 88.03 | K25: Assurances/Mutuelle
E26: Suravenir Garanties Vie | F26: 18.99 | G26: x | H26: =IF(G26="x",F26,0) -> 18.99 | K26: Assurances/Mutuelle
E27: Joséphine | F27: 20 | G27: x | H27: =IF(G27="x",F27,0) -> 20 | K27: Divers
E28: Canal Plus | F28: 21.99 | G28: x | H28: =IF(G28="x",F28,0) -> 21.99 | K28: Internet/Téléphone
H29: =IF(G29="x",F29,0) -> 0 | K29: Voiture/Déplacement
E30: Keolis Elouen | F30: 21.4 | G30: x | H30: =IF(G30="x",F30,0) -> 21.4 | K30: Voiture/Déplacement
E31: Apple | F31: 0.99 | G31: x | H31: =IF(G31="x",F31,0) -> 0.99 | K31: Internet/Téléphone
E32: Apple | F32: 0.99 | G32: x | H32: =IF(G32="x",F32,0) -> 0.99 | K32: Internet/Téléphone
E33: Apple | F33: 16.99 | G33: x | H33: =IF(G33="x",F33,0) -> 16.99 | K33: Internet/Téléphone
E34: St Charles | F34: 278.3 | H34: =IF(G34="x",F34,0) -> 0 | K34: Scolarité
E35: Ménage | F35: 170 | H35: =IF(G35="x",F35,0) -> 0 | K35: Logement
E36: Urssaaf | F36: 129.86 | G36: x | H36: =IF(G36="x",F36,0) -> 129.86 | K36: Logement
E37: Cotisation Eurocompte | F37: 19.03 | G37: x | H37: =IF(G37="x",F37,0) -> 19.03 | K37: Charges
E38: Indivision | F38: 33.89 | G38: x | H38: =IF(G38="x",F38,0) -> 33.89 | K38: Charges
A39: Etat mois précédent | C39: ='Juillet 2026'!D43 -> #REF!
A40: Recettes fixes | C40: =SUM(C2:C6) -> 7336.91 | E40: Somme dépenses prévues | F40: =SUM(F2:F38) -> 4451.68 | G40: Somme dépenses réelles | H40: =SUM(H2:H38) -> 3938.38 | I40: Delta moins les exceptions
A41: Recettes additionnelles du mois | C41: =SUM(C8:C35) -> 3593.61 | E41: Reste previsionnel | F41: =C42-F40 -> #REF! | G41: Delta du mois | H41: =C39+C40+C41-H40-F42 -> #REF!
A42: Total Recettes | C42: =SUM(C39:C41) -> #REF! | E42: Somme dépenses non prévues | F42: =SUM(J44:J249) -> 7214.47
...

Sheet Juillet 2026
B1: Recettes | E1: Dépenses | K1: Cadeau
B3: Salaire Pierre | C3: 5651.76 | E3: Loyer Elouen | F3: 669.7 | G3: x | H3: =IF(G3="x",F3,0) -> 669.7 | K3: Logement
B4: Salaire Sterenn | C4: 1938.46 | E4: Argent de poche Elouen | H4: =IF(G4="x",F4,0) -> 0 | K4: Charges
B5: CAF | C5: 114.19 | E5: Engie Elouen | F5: 70 | G5: x | H5: =IF(G5="x",F5,0) -> 70 | K5: Charges
E6: Argent de poche Arthur | F6: 14.99 | G6: x | H6: =IF(G6="x",F6,0) -> 14.99 | K6: Charges
E7: Prêt 25 | F7: 995.15 | G7: x | H7: =IF(G7="x",F7,0) -> 995.15 | K7: Logement
B8: Note de frais Igienair | C8: 261.76 | E8: Prêt 15 | F8: 883.42 | G8: x | H8: =IF(G8="x",F8,0) -> 883.42 | K8: Logement
B9: Note de Frais Altran | C9: 69.75 | E9: Assurances prêt | F9: 11.46 | G9: x | H9: =IF(G9="x",F9,0) -> 11.46 | K9: Logement
B10: Pret Arthur Scolarité | C10: 105 | E10: Assurances prêt | F10: 32.57 | G10: x | H10: =IF(G10="x",F10,0) -> 32.57 | K10: Logement
B11: Pret Arthur Scolarité | C11: 178 | E11: Assurances prêt | F11: 79.98 | G11: x | H11: =IF(G11="x",F11,0) -> 79.98 | K11: Logement
B12: Cadeau copains | C12: 580 | E12: Assurances prêt | F12: 28.49 | G12: x | H12: =IF(G12="x",F12,0) -> 28.49 | K12: Logement
B13: Scolarité Arthur/Elouen | C13: 720 | E13: Disney | F13: 6.99 | G13: x | H13: =IF(G13="x",F13,0) -> 6.99 | K13: Internet/Téléphone
B14: Baby Sitting Arthur | C14: 40 | E14: EDF Arthur | F14: 65 | G14: x | H14: =IF(G14="x",F14,0) -> 65 | K14: Charges
B15: Virement Impots | C15: 3165 | E15: EkWateur | F15: 208 | G15: x | H15: =IF(G15="x",F15,0) -> 208 | K15: Charges
E16: Sosh Maison | F16: 24.99 | G16: x | H16: =IF(G16="x",F16,0) -> 24.99 | K16: Internet/Téléphone
E17: Sosh Arthur | F17: 14.99 | G17: x | H17: =IF(G17="x",F17,0) -> 14.99 | K17: Internet/Téléphone
E18: Sosh Ael | F18: 14.99 | H18: =IF(G18="x",F18,0) -> 0 | K18: Internet/Téléphone
E19: Sosh Elouen | F19: 14.99 | G19: x | H19: =IF(G19="x",F19,0) -> 14.99 | K19: Internet/Téléphone
E20: Sosh Sterenn | F20: 10.99 | G20: x | H20: =IF(G20="x",F20,0) -> 10.99 | K20: Internet/Téléphone
E21: Mutuelle | F21: 104.98 | G21: x | H21: =IF(G21="x",F21,0) -> 104.98 | K21: Assurances/Mutuelle
E23: AxaHabitation | F23: 62.88 | G23: x | H23: =IF(G23="x",F23,0) -> 62.88 | K23: Assurances/Mutuelle
E24: VW LDD | F24: 331.65 | G24: x | H24: =IF(G24="x",F24,0) -> 331.65 | K24: Voiture/Déplacement
E25: Axa Voiture | F25: 88.03 | G25: x | H25: =IF(G25="x",F25,0) -> 88.03 | K25: Assurances/Mutuelle
E26: Suravenir Garanties Vie | F26: 18.99 | G26: x | H26: =IF(G26="x",F26,0) -> 18.99 | K26: Assurances/Mutuelle
E27: Joséphine | F27: 20 | G27: x | H27: =IF(G27="x",F27,0) -> 20 | K27: Divers
E28: Canal Plus | F28: 21.99 | G28: x | H28: =IF(G28="x",F28,0) -> 21.99 | K28: Internet/Téléphone
H29: =IF(G29="x",F29,0) -> 0 | K29: Voiture/Déplacement
E30: Keolis Elouen | F30: 21.4 | G30: x | H30: =IF(G30="x",F30,0) -> 21.4 | K30: Voiture/Déplacement
E31: Apple | F31: 0.99 | G31: x | H31: =IF(G31="x",F31,0) -> 0.99 | K31: Internet/Téléphone
E32: Apple | F32: 0.99 | G32: x | H32: =IF(G32="x",F32,0) -> 0.99 | K32: Internet/Téléphone
E33: Apple | F33: 16.99 | G33: x | H33: =IF(G33="x",F33,0) -> 16.99 | K33: Internet/Téléphone
E34: St Charles | F34: 278.3 | G34: x | H34: =IF(G34="x",F34,0) -> 278.3 | K34: Scolarité
E35: Ménage | F35: 170 | G35: x | H35: =IF(G35="x",F35,0) -> 170 | K35: Logement
E36: Urssaaf | F36: 136 | G36: x | H36: =IF(G36="x",F36,0) -> 136 | K36: Logement
E37: Cotisation Eurocompte | F37: 19.03 | G37: x | H37: =IF(G37="x",F37,0) -> 19.03 | K37: Charges
E38: Indivision | F38: 33.89 | G38: x | H38: =IF(G38="x",F38,0) -> 33.89 | K38: Charges
A39: Etat mois précédent | C39: ='Juin 2026'!D43 -> #REF!
A40: Recettes fixes | C40: =SUM(C2:C6) -> 7704.41 | E40: Somme dépenses prévues | F40: =SUM(F2:F38) -> 4472.81 | G40: Somme dépenses réelles | H40: =SUM(H2:H38) -> 4457.82 | I40: Delta moins les exceptions
A41: Recettes additionnelles du mois | C41: =SUM(C8:C35) -> 5119.51 | E41: Reste previsionnel | F41: =C42-F40 -> #REF! | G41: Delta du mois | H41: =C39+C40+C41-H40-F42 -> #REF!
A42: Total Recettes | C42: =SUM(C39:C41) -> #REF! | E42: Somme dépenses non prévues | F42: =SUM(J44:J247) -> 8324.92
...

Sheet Juin 2026
B1: Recettes | E1: Dépenses | K1: Cadeau
B3: Salaire Pierre | C3: 5273.11 | E3: Loyer Elouen | F3: 669.7 | G3: x | H3: =IF(G3="x",F3,0) -> 669.7 | K3: Logement
B4: Salaire Sterenn | C4: 1828.73 | E4: Argent de poche Elouen | H4: =IF(G4="x",F4,0) -> 0 | K4: Charges
B5: CAF | C5: 114.19 | E5: Engie Elouen | F5: 70 | G5: x | H5: =IF(G5="x",F5,0) -> 70 | K5: Charges
E6: Argent de poche Arthur | F6: 14.99 | G6: x | H6: =IF(G6="x",F6,0) -> 14.99 | K6: Charges
E7: Prêt 25 | F7: 995.15 | G7: x | H7: =IF(G7="x",F7,0) -> 995.15 | K7: Logement
E8: Prêt 15 | F8: 883.42 | G8: x | H8: =IF(G8="x",F8,0) -> 883.42 | K8: Logement
B9: Mutuelle | C9: 9.45 | E9: Assurances prêt | F9: 11.46 | G9: x | H9: =IF(G9="x",F9,0) -> 11.46 | K9: Logement
B10: Note de Frais Igienair | C10: 76.64 | E10: Assurances prêt | F10: 32.57 | G10: x | H10: =IF(G10="x",F10,0) -> 32.57 | K10: Logement
B11: Mutuelle | C11: 9 | E11: Assurances prêt | F11: 79.98 | G11: x | H11: =IF(G11="x",F11,0) -> 79.98 | K11: Logement
B12: Remboursement Amazon | C12: 43.34 | E12: Assurances prêt | F12: 28.49 | G12: x | H12: =IF(G12="x",F12,0) -> 28.49 | K12: Logement
B13: Padel Edouard | C13: 4 | E13: Disney | F13: 6.99 | G13: x | H13: =IF(G13="x",F13,0) -> 6.99 | K13: Internet/Téléphone
B14: Padel Didier | C14: 4 | E14: EDF Arthur | F14: 65 | G14: x | H14: =IF(G14="x",F14,0) -> 65 | K14: Charges
B15: Note de Frais Cap | C15: 57.3 | E15: EkWateur | F15: 208 | G15: x | H15: =IF(G15="x",F15,0) -> 208 | K15: Charges
B16: Mutuelle Elouen | C16: 30.9 | E16: Sosh Maison | F16: 24.99 | G16: x | H16: =IF(G16="x",F16,0) -> 24.99 | K16: Internet/Téléphone
B17: Epargne | C17: 500 | E17: Sosh Arthur | F17: 14.99 | G17: x | H17: =IF(G17="x",F17,0) -> 14.99 | K17: Internet/Téléphone
B18: Epargne | C18: 300 | E18: Sosh Ael | F18: 14.99 | H18: =IF(G18="x",F18,0) -> 0 | K18: Internet/Téléphone
B19: Remboursement MicroOnde Papa | C19: 91 | E19: Sosh Elouen | F19: 14.99 | G19: x | H19: =IF(G19="x",F19,0) -> 14.99 | K19: Internet/Téléphone
B20: CPAM | C20: 4 | E20: Sosh Sterenn | F20: 10.99 | G20: x | H20: =IF(G20="x",F20,0) -> 10.99 | K20: Internet/Téléphone
B21: Remboursement Ael | C21: 168 | E21: Mutuelle | F21: 104.98 | G21: x | H21: =IF(G21="x",F21,0) -> 104.98 | K21: Assurances/Mutuelle
E23: AxaHabitation | F23: 62.88 | G23: x | H23: =IF(G23="x",F23,0) -> 62.88 | K23: Assurances/Mutuelle
E24: VW LDD | F24: 331.65 | G24: x | H24: =IF(G24="x",F24,0) -> 331.65 | K24: Voiture/Déplacement
E25: Axa Voiture | F25: 88.03 | G25: x | H25: =IF(G25="x",F25,0) -> 88.03 | K25: Assurances/Mutuelle
E26: Suravenir Garanties Vie | F26: 19 | H26: =IF(G26="x",F26,0) -> 0 | K26: Assurances/Mutuelle
E27: Joséphine | F27: 20 | G27: x | H27: =IF(G27="x",F27,0) -> 20 | K27: Divers
E28: Canal Plus | F28: 21.99 | G28: x | H28: =IF(G28="x",F28,0) -> 21.99 | K28: Internet/Téléphone
H29: =IF(G29="x",F29,0) -> 0 | K29: Voiture/Déplacement
E30: Keolis Elouen | F30: 21.4 | G30: x | H30: =IF(G30="x",F30,0) -> 21.4 | K30: Voiture/Déplacement
E31: Apple | F31: 0.99 | G31: x | H31: =IF(G31="x",F31,0) -> 0.99 | K31: Internet/Téléphone
E32: Apple | F32: 0.99 | H32: =IF(G32="x",F32,0) -> 0 | K32: Internet/Téléphone
E33: Apple | F33: 16.99 | H33: =IF(G33="x",F33,0) -> 0 | K33: Internet/Téléphone
E34: St Charles | F34: 196.9 | G34: x | H34: =IF(G34="x",F34,0) -> 196.9 | K34: Scolarité
E35: Ménage | F35: 68 | G35: x | H35: =IF(G35="x",F35,0) -> 68 | K35: Logement
E36: Urssaaf | F36: 78.43 | G36: x | H36: =IF(G36="x",F36,0) -> 78.43 | K36: Logement
E37: Cotisation Eurocompte | F37: 19.03 | G37: x | H37: =IF(G37="x",F37,0) -> 19.03 | K37: Charges
E38: Indivision | F38: 33.89 | G38: x | H38: =IF(G38="x",F38,0) -> 33.89 | K38: Charges
A39: Etat mois précédent | C39: ='Mai 2026'!D44 -> #REF!
A40: Recettes fixes | C40: =SUM(C2:C6) -> 7216.03 | E40: Somme dépenses prévues | F40: =SUM(F2:F38) -> 4231.85 | G40: Somme dépenses réelles | H40: =SUM(H2:H38) -> 4179.88 | I40: Delta moins les exceptions
A41: Recettes additionnelles du mois | C41: =SUM(C8:C35) -> 1297.63 | E41: Reste previsionnel | F41: =C42-F40 -> #REF! | G41: Delta du mois | H41: =C39+C40+C41-H40-F42 -> #REF!
A42: Total Recettes | C42: =SUM(C39:C41) -> #REF! | E42: Somme dépenses non prévues | F42: =SUM(J44:J247) -> 3893.13
...

Sheet Mai 2026
B1: Recettes | E1: Dépenses | K1: Cadeau
B3: Salaire Pierre | C3: 5357.67 | E3: Loyer Elouen | F3: 669.7 | G3: x | H3: =IF(G3="x",F3,0) -> 669.7 | K3: Logement
B4: Salaire Sterenn | C4: 2011.6 | E4: Argent de poche Elouen | H4: =IF(G4="x",F4,0) -> 0 | K4: Charges
B5: CAF | C5: 114.19 | E5: Engie Elouen | F5: 70 | G5: x | H5: =IF(G5="x",F5,0) -> 70 | K5: Charges
E6: Argent de poche Arthur | F6: 164.99 | G6: x | H6: =IF(G6="x",F6,0) -> 164.99 | K6: Charges
E7: Prêt 25 | F7: 995.15 | G7: x | H7: =IF(G7="x",F7,0) -> 995.15 | K7: Logement
E8: Prêt 15 | F8: 883.42 | G8: x | H8: =IF(G8="x",F8,0) -> 883.42 | K8: Logement
B9: Remboursement Suravenir | C9: 51.15 | E9: Assurances prêt | F9: 11.46 | G9: x | H9: =IF(G9="x",F9,0) -> 11.46 | K9: Logement
B10: Note de frais CAP | C10: 55.3 | E10: Assurances prêt | F10: 32.57 | G10: x | H10: =IF(G10="x",F10,0) -> 32.57 | K10: Logement
B11: Remboursement La Redoute | C11: 39.99 | E11: Assurances prêt | F11: 79.98 | G11: x | H11: =IF(G11="x",F11,0) -> 79.98 | K11: Logement
B12: Colle Nolwenn | C12: 5 | E12: Assurances prêt | F12: 28.49 | G12: x | H12: =IF(G12="x",F12,0) -> 28.49 | K12: Logement
B13: Remboursement mutuelle | C13: 9 | E13: Disney | F13: 6.99 | G13: x | H13: =IF(G13="x",F13,0) -> 6.99 | K13: Internet/Téléphone
B14: Epargne | C14: 1000 | E14: EDF Arthur | F14: 65 | G14: x | H14: =IF(G14="x",F14,0) -> 65 | K14: Charges
B15: CPAM | C15: 17 | E15: EkWateur | F15: 208 | G15: x | H15: =IF(G15="x",F15,0) -> 208 | K15: Charges
B16: CPAM | C16: 12 | E16: Sosh Maison | F16: 24.99 | G16: x | H16: =IF(G16="x",F16,0) -> 24.99 | K16: Internet/Téléphone
B17: Mutuelle | C17: 18 | E17: Sosh Arthur | F17: 14.99 | G17: x | H17: =IF(G17="x",F17,0) -> 14.99 | K17: Internet/Téléphone
B18: Mutuelle | C18: 9 | E18: Sosh Ael | F18: 14.99 | H18: =IF(G18="x",F18,0) -> 0 | K18: Internet/Téléphone
B19: CPAM | C19: 20.05 | E19: Sosh Elouen | F19: 14.99 | G19: x | H19: =IF(G19="x",F19,0) -> 14.99 | K19: Internet/Téléphone
E20: Sosh Sterenn | F20: 10.99 | G20: x | H20: =IF(G20="x",F20,0) -> 10.99 | K20: Internet/Téléphone
E21: Mutuelle | F21: 104.98 | G21: x | H21: =IF(G21="x",F21,0) -> 104.98 | K21: Assurances/Mutuelle
E23: AxaHabitation | F23: 69.38 | G23: x | H23: =IF(G23="x",F23,0) -> 69.38 | K23: Assurances/Mutuelle
E24: VW LDD | F24: 331.65 | G24: x | H24: =IF(G24="x",F24,0) -> 331.65 | K24: Voiture/Déplacement
E25: Suravenir Voiture | F25: 94.53 | G25: x | H25: =IF(G25="x",F25,0) -> 94.53 | K25: Assurances/Mutuelle
E26: Suravenir Garanties Vie | F26: 19 | H26: =IF(G26="x",F26,0) -> 0 | K26: Assurances/Mutuelle
E27: Joséphine | F27: 20 | G27: x | H27: =IF(G27="x",F27,0) -> 20 | K27: Divers
E28: Canal Plus | F28: 21.99 | G28: x | H28: =IF(G28="x",F28,0) -> 21.99 | K28: Internet/Téléphone
H29: =IF(G29="x",F29,0) -> 0 | K29: Voiture/Déplacement
E30: Keolis Elouen | F30: 21.4 | G30: x | H30: =IF(G30="x",F30,0) -> 21.4 | K30: Voiture/Déplacement
E31: Apple | F31: 0.99 | G31: x | H31: =IF(G31="x",F31,0) -> 0.99 | K31: Internet/Téléphone
E32: Apple | F32: 0.99 | G32: x | H32: =IF(G32="x",F32,0) -> 0.99 | K32: Internet/Téléphone
E33: Apple | F33: 16.99 | G33: x | H33: =IF(G33="x",F33,0) -> 16.99 | K33: Internet/Téléphone
E34: St Charles | F34: 278.3 | G34: x | H34: =IF(G34="x",F34,0) -> 278.3 | K34: Scolarité
E35: Ménage | F35: 102 | G35: x | H35: =IF(G35="x",F35,0) -> 102 | K35: Logement
E36: Urssaaf | F36: 129.86 | G36: x | H36: =IF(G36="x",F36,0) -> 129.86 | K36: Logement
E37: Cotisation Eurocompte | F37: 19.03 | G37: x | H37: =IF(G37="x",F37,0) -> 19.03 | K37: Charges
E38: Indivision | F38: 33.89 | G38: x | H38: =IF(G38="x",F38,0) -> 33.89 | K38: Charges
A39: Etat mois précédent | C39: ='Avril 2026'!D43 -> #REF!
A40: Recettes fixes | C40: =SUM(C2:C6) -> 7483.46 | E40: Somme dépenses prévues | F40: =SUM(F2:F38) -> 4561.68 | G40: Somme dépenses réelles | H40: =SUM(H2:H38) -> 4527.69 | I40: Delta moins les exceptions
A41: Recettes additionnelles du mois | C41: =SUM(C8:C35) -> 1236.49 | E41: Reste previsionnel | F41: =C42-F40 -> #REF! | G41: Delta du mois | H41: =C39+C40+C41-H40-F42 -> #REF!
A42: Total Recettes | C42: =SUM(C39:C41) -> #REF! | E42: Somme dépenses non prévues | F42: =SUM(J44:J246) -> 4646.71
...

Sheet Avril 2026
B1: Recettes | E1: Dépenses | K1: Cadeau
B3: Salaire Pierre | C3: 6365.48 | E3: Loyer Elouen | F3: 669.7 | G3: x | H3: =IF(G3="x",F3,0) -> 669.7 | K3: Logement
B4: Salaire Sterenn | C4: 1828.73 | E4: Argent de poche Elouen | H4: =IF(G4="x",F4,0) -> 0 | K4: Charges
B5: CAF | C5: 113.3 | E5: Engie Elouen | F5: 70 | G5: x | H5: =IF(G5="x",F5,0) -> 70 | K5: Charges
E6: Argent de poche Arthur | F6: 164.99 | G6: x | H6: =IF(G6="x",F6,0) -> 164.99 | K6: Charges
E7: Prêt 25 | F7: 995.15 | G7: x | H7: =IF(G7="x",F7,0) -> 995.15 | K7: Logement
B8: Virement Mamou | C8: 150 | E8: Prêt 15 | F8: 883.42 | G8: x | H8: =IF(G8="x",F8,0) -> 883.42 | K8: Logement
B9: Note de Frais Igienair | C9: 121.83 | E9: Assurances prêt | F9: 11.46 | G9: x | H9: =IF(G9="x",F9,0) -> 11.46 | K9: Logement
B10: Stephanie Charrier | C10: 21 | E10: Assurances prêt | F10: 32.57 | G10: x | H10: =IF(G10="x",F10,0) -> 32.57 | K10: Logement
B11: Remboursement Suravenir | C11: 2.18 | E11: Assurances prêt | F11: 79.98 | G11: x | H11: =IF(G11="x",F11,0) -> 79.98 | K11: Logement
B12: Remboursement Suravenir | C12: 4.97 | E12: Assurances prêt | F12: 28.49 | G12: x | H12: =IF(G12="x",F12,0) -> 28.49 | K12: Logement
E13: Disney | F13: 6.99 | G13: x | H13: =IF(G13="x",F13,0) -> 6.99 | K13: Internet/Téléphone
E14: EDF Arthur | F14: 65 | G14: x | H14: =IF(G14="x",F14,0) -> 65 | K14: Charges
E15: EkWateur | F15: 208 | G15: x | H15: =IF(G15="x",F15,0) -> 208 | K15: Charges
E16: Sosh Maison | F16: 24.99 | G16: x | H16: =IF(G16="x",F16,0) -> 24.99 | K16: Internet/Téléphone
E17: Sosh Arthur | F17: 14.99 | G17: x | H17: =IF(G17="x",F17,0) -> 14.99 | K17: Internet/Téléphone
E18: Sosh Ael | F18: 14.99 | G18: x | H18: =IF(G18="x",F18,0) -> 14.99 | K18: Internet/Téléphone
E19: Sosh Elouen | F19: 14.99 | H19: =IF(G19="x",F19,0) -> 0 | K19: Internet/Téléphone
E20: Sosh Sterenn | F20: 10.99 | G20: x | H20: =IF(G20="x",F20,0) -> 10.99 | K20: Internet/Téléphone
E21: Mutuelle | F21: 104.98 | G21: x | H21: =IF(G21="x",F21,0) -> 104.98 | K21: Assurances/Mutuelle
E23: Suravenir Habitation | F23: 60.09 | G23: x | H23: =IF(G23="x",F23,0) -> 60.09 | K23: Assurances/Mutuelle
E24: VW LDD | F24: 331.65 | G24: x | H24: =IF(G24="x",F24,0) -> 331.65 | K24: Voiture/Déplacement
E25: Suravenir Voiture | F25: 133.7 | G25: x | H25: =IF(G25="x",F25,0) -> 133.7 | K25: Assurances/Mutuelle
E26: Suravenir Garanties Vie | F26: 29.97 | G26: x | H26: =IF(G26="x",F26,0) -> 29.97 | K26: Assurances/Mutuelle
E27: Joséphine | F27: 20 | G27: x | H27: =IF(G27="x",F27,0) -> 20 | K27: Divers
E28: Canal Plus | F28: 21.99 | G28: x | H28: =IF(G28="x",F28,0) -> 21.99 | K28: Internet/Téléphone
H29: =IF(G29="x",F29,0) -> 0 | K29: Voiture/Déplacement
E30: Keolis Elouen | F30: 21.4 | G30: x | H30: =IF(G30="x",F30,0) -> 21.4 | K30: Voiture/Déplacement
E31: Apple | F31: 0.99 | G31: x | H31: =IF(G31="x",F31,0) -> 0.99 | K31: Internet/Téléphone
E32: Apple | F32: 16.99 | G32: x | H32: =IF(G32="x",F32,0) -> 16.99 | K32: Internet/Téléphone
E33: St Charles | F33: 178.3 | G33: x | H33: =IF(G33="x",F33,0) -> 178.3 | K33: Scolarité
E34: Ménage | F34: 170 | G34: x | H34: =IF(G34="x",F34,0) -> 170 | K34: Logement
E35: Urssaaf | F35: 78.43 | G35: x | H35: =IF(G35="x",F35,0) -> 78.43 | K35: Logement
E36: Cotisation Eurocompte | F36: 16.85 | G36: x | H36: =IF(G36="x",F36,0) -> 16.85 | K36: Charges
E37: Indivision | F37: 33.89 | G37: x | H37: =IF(G37="x",F37,0) -> 33.89 | K37: Charges
A39: Etat mois précédent | C39: ='Mars 2026'!D43 -> #REF!
A40: Recettes fixes | C40: =SUM(C2:C6) -> 8307.51 | E40: Somme dépenses prévues | F40: =SUM(F2:F38) -> 4515.93 | G40: Somme dépenses réelles | H40: =SUM(H2:H38) -> 4500.94 | I40: Delta moins les exceptions
A41: Recettes additionnelles du mois | C41: =SUM(C8:C35) -> 299.98 | E41: Reste previsionnel | F41: =C42-F40 -> #REF! | G41: Delta du mois | H41: =C39+C40+C41-H40-F42 -> #REF!
A42: Total Recettes | C42: =SUM(C39:C41) -> #REF! | E42: Somme dépenses non prévues | F42: =SUM(J44:J246) -> 3979.86
A43: Reste prévu | B43: =$C$42-$F$40-$F$42 -> #REF! | C43: Reste réel | D43: =$C$42-$H$40-$F$42 -> #REF!
...

Sheet Mars 2026
B1: Recettes | E1: Dépenses | K1: Cadeau
B3: Salaire Pierre | C3: 5258.61 | E3: Loyer Elouen | F3: 669.7 | G3: x | H3: =IF(G3="x",F3,0) -> 669.7 | K3: Logement
B4: Salaire Sterenn | C4: 1828.73 | E4: Argent de poche Elouen | H4: =IF(G4="x",F4,0) -> 0 | K4: Charges
B5: CAF | C5: 113.3 | E5: Engie Elouen | F5: 70 | G5: x | H5: =IF(G5="x",F5,0) -> 70 | K5: Charges
E6: Argent de poche Arthur | F6: 164.99 | G6: x | H6: =IF(G6="x",F6,0) -> 164.99 | K6: Charges
E7: Prêt 25 | F7: 995.15 | G7: x | H7: =IF(G7="x",F7,0) -> 995.15 | K7: Logement
E8: Prêt 15 | F8: 883.42 | G8: x | H8: =IF(G8="x",F8,0) -> 883.42 | K8: Logement
B9: Frais Igienair | C9: 93.15 | E9: Assurances prêt | F9: 11.46 | G9: x | H9: =IF(G9="x",F9,0) -> 11.46 | K9: Logement
B10: Mutuelle | C10: 10.5 | E10: Assurances prêt | F10: 32.57 | G10: x | H10: =IF(G10="x",F10,0) -> 32.57 | K10: Logement
B11: Epargne Travaux | C11: 599.17 | E11: Assurances prêt | F11: 79.98 | G11: x | H11: =IF(G11="x",F11,0) -> 79.98 | K11: Logement
B12: Remboursement Mitigeur Lidl | C12: 26.99 | E12: Assurances prêt | F12: 28.49 | G12: x | H12: =IF(G12="x",F12,0) -> 28.49 | K12: Logement
B13: CPAM | C13: 4 | E13: Disney | F13: 6.99 | G13: x | H13: =IF(G13="x",F13,0) -> 6.99 | K13: Internet/Téléphone
B14: Epargne Travaux | C14: 450 | E14: EDF Arthur | F14: 65 | G14: x | H14: =IF(G14="x",F14,0) -> 65 | K14: Charges
B15: Edouard Padel | C15: 4.2 | E15: EkWateur | F15: 208 | G15: x | H15: =IF(G15="x",F15,0) -> 208 | K15: Charges
B16: Jean Marie Raclette | C16: 15.67 | E16: Sosh Maison | F16: 24.99 | G16: x | H16: =IF(G16="x",F16,0) -> 24.99 | K16: Internet/Téléphone
B17: Epargne Travaux | C17: 178.72 | E17: Sosh Arthur | F17: 14.99 | G17: x | H17: =IF(G17="x",F17,0) -> 14.99 | K17: Internet/Téléphone
E18: Sosh Ael | F18: 14.99 | G18: x | H18: =IF(G18="x",F18,0) -> 14.99 | K18: Internet/Téléphone
E19: Sosh Elouen | F19: 14.99 | G19: x | H19: =IF(G19="x",F19,0) -> 14.99 | K19: Internet/Téléphone
E20: Sosh Sterenn | F20: 10.99 | G20: x | H20: =IF(G20="x",F20,0) -> 10.99 | K20: Internet/Téléphone
E21: Mutuelle | F21: 104.98 | G21: x | H21: =IF(G21="x",F21,0) -> 104.98 | K21: Assurances/Mutuelle
E23: Suravenir Habitation | F23: 60.09 | G23: x | H23: =IF(G23="x",F23,0) -> 60.09 | K23: Assurances/Mutuelle
E24: VW LDD | F24: 331.65 | G24: x | H24: =IF(G24="x",F24,0) -> 331.65 | K24: Voiture/Déplacement
E25: Suravenir Voiture | F25: 133.7 | G25: x | H25: =IF(G25="x",F25,0) -> 133.7 | K25: Assurances/Mutuelle
E26: Suravenir Garanties Vie | F26: 29.97 | G26: x | H26: =IF(G26="x",F26,0) -> 29.97 | K26: Assurances/Mutuelle
E27: Joséphine | F27: 20 | G27: x | H27: =IF(G27="x",F27,0) -> 20 | K27: Divers
E28: Canal Plus | F28: 21.99 | G28: x | H28: =IF(G28="x",F28,0) -> 21.99 | K28: Internet/Téléphone
H29: =IF(G29="x",F29,0) -> 0 | K29: Voiture/Déplacement
E30: Keolis Elouen | F30: 21.4 | G30: x | H30: =IF(G30="x",F30,0) -> 21.4 | K30: Voiture/Déplacement
E31: Apple | F31: 0.99 | G31: x | H31: =IF(G31="x",F31,0) -> 0.99 | K31: Internet/Téléphone
E32: Apple | F32: 16.99 | G32: x | H32: =IF(G32="x",F32,0) -> 16.99 | K32: Internet/Téléphone
E33: St Charles | F33: 178.3 | G33: x | H33: =IF(G33="x",F33,0) -> 178.3 | K33: Scolarité
E34: Ménage | F34: 102 | G34: x | H34: =IF(G34="x",F34,0) -> 102 | K34: Logement
E35: Urssaaf | F35: 104.6 | G35: x | H35: =IF(G35="x",F35,0) -> 104.6 | K35: Logement
E36: Cotisation Eurocompte | F36: 19.03 | G36: x | H36: =IF(G36="x",F36,0) -> 19.03
E37: Indivision | F37: 33.89 | G37: x | H37: =IF(G37="x",F37,0) -> 33.89
A39: Etat mois précédent | C39: ='Fevrier 2026'!D43 -> #REF!
A40: Recettes fixes | C40: =SUM(C2:C6) -> 7200.64 | E40: Somme dépenses prévues | F40: =SUM(F2:F38) -> 4476.28 | G40: Somme dépenses réelles | H40: =SUM(H2:H38) -> 4476.28 | I40: Delta moins les exceptions
A41: Recettes additionnelles du mois | C41: =SUM(C8:C35) -> 1382.4 | E41: Reste previsionnel | F41: =C42-F40 -> #REF! | G41: Delta du mois | H41: =C39+C40+C41-H40-F42 -> #REF!
A42: Total Recettes | C42: =SUM(C39:C41) -> #REF! | E42: Somme dépenses non prévues | F42: =SUM(J44:J246) -> 3943.44
A43: Reste prévu | B43: =$C$42-$F$40-$F$42 -> #REF! | C43: Reste réel | D43: =$C$42-$H$40-$F$42 -> #REF!
...

Sheet Fevrier 2026
B1: Recettes | E1: Dépenses | K1: Cadeau
B3: Salaire Pierre | C3: 5245.11 | E3: Loyer Elouen | F3: 669.7 | G3: x | H3: =IF(G3="x",F3,0) -> 669.7 | K3: Logement
B4: Salaire Sterenn | C4: 1828.73 | E4: Argent de poche Elouen | H4: =IF(G4="x",F4,0) -> 0 | K4: Charges
B5: CAF | C5: 113.3 | E5: Engie Elouen | F5: 70 | G5: x | H5: =IF(G5="x",F5,0) -> 70 | K5: Charges
E6: Argent de poche Arthur | F6: 164.99 | G6: x | H6: =IF(G6="x",F6,0) -> 164.99 | K6: Charges
E7: Prêt 25 | F7: 995.15 | G7: x | H7: =IF(G7="x",F7,0) -> 995.15 | K7: Logement
B8: CPAM | C8: 19 | E8: Prêt 15 | F8: 883.42 | G8: x | H8: =IF(G8="x",F8,0) -> 883.42 | K8: Logement
B9: Note de Frais | C9: 72.32 | E9: Assurances prêt | F9: 11.46 | G9: x | H9: =IF(G9="x",F9,0) -> 11.46 | K9: Logement
B10: Titouan | C10: 16 | E10: Assurances prêt | F10: 32.57 | G10: x | H10: =IF(G10="x",F10,0) -> 32.57 | K10: Logement
B11: Mateo | C11: 16 | E11: Assurances prêt | F11: 79.98 | G11: x | H11: =IF(G11="x",F11,0) -> 79.98 | K11: Logement
B12: Aurel | C12: 16 | E12: Assurances prêt | F12: 28.49 | G12: x | H12: =IF(G12="x",F12,0) -> 28.49 | K12: Logement
B13: Sandrine | C13: 16 | E13: Disney | F13: 6.99 | G13: x | H13: =IF(G13="x",F13,0) -> 6.99 | K13: Internet/Téléphone
B14: Fred | C14: 15.67 | E14: EDF Arthur | F14: 43.96 | G14: x | H14: =IF(G14="x",F14,0) -> 43.96 | K14: Charges
B15: Edouard | C15: 15.67 | E15: EkWateur | F15: 208 | G15: x | H15: =IF(G15="x",F15,0) -> 208 | K15: Charges
B16: Sebastien | C16: 16 | E16: Sosh Maison | F16: 24.99 | G16: x | H16: =IF(G16="x",F16,0) -> 24.99 | K16: Internet/Téléphone
B17: Mutuelle | C17: 9 | E17: Sosh Arthur | F17: 14.99 | G17: x | H17: =IF(G17="x",F17,0) -> 14.99 | K17: Internet/Téléphone
B18: Telephone Ael | C18: 85 | E18: Sosh Ael | F18: 14.99 | H18: =IF(G18="x",F18,0) -> 0 | K18: Internet/Téléphone
E19: Sosh Elouen | F19: 14.99 | H19: =IF(G19="x",F19,0) -> 0 | K19: Internet/Téléphone
E20: Sosh Sterenn | F20: 10.99 | G20: x | H20: =IF(G20="x",F20,0) -> 10.99 | K20: Internet/Téléphone
E21: Mutuelle | F21: 104.98 | G21: x | H21: =IF(G21="x",F21,0) -> 104.98 | K21: Assurances/Mutuelle
E23: Suravenir Habitation | F23: 60.09 | G23: x | H23: =IF(G23="x",F23,0) -> 60.09 | K23: Assurances/Mutuelle
E24: VW LDD | F24: 331.65 | G24: x | H24: =IF(G24="x",F24,0) -> 331.65 | K24: Voiture/Déplacement
E25: Suravenir Voiture | F25: 133.7 | G25: x | H25: =IF(G25="x",F25,0) -> 133.7 | K25: Assurances/Mutuelle
E26: Suravenir Garanties Vie | F26: 29.97 | G26: x | H26: =IF(G26="x",F26,0) -> 29.97 | K26: Assurances/Mutuelle
E27: Joséphine | F27: 20 | G27: x | H27: =IF(G27="x",F27,0) -> 20 | K27: Divers
E28: Canal Plus | F28: 21.99 | G28: x | H28: =IF(G28="x",F28,0) -> 21.99 | K28: Internet/Téléphone
H29: =IF(G29="x",F29,0) -> 0 | K29: Voiture/Déplacement
E30: Keolis Elouen | F30: 21.4 | G30: x | H30: =IF(G30="x",F30,0) -> 21.4 | K30: Voiture/Déplacement
E31: Apple | F31: 0.99 | G31: x | H31: =IF(G31="x",F31,0) -> 0.99 | K31: Internet/Téléphone
E32: Apple | F32: 16.99 | G32: x | H32: =IF(G32="x",F32,0) -> 16.99 | K32: Internet/Téléphone
E33: St Charles | F33: 172.1 | G33: x | H33: =IF(G33="x",F33,0) -> 172.1 | K33: Scolarité
E34: Ménage | F34: 68 | H34: =IF(G34="x",F34,0) -> 0 | K34: Logement
E35: Urssaaf | F35: 104.66 | G35: x | H35: =IF(G35="x",F35,0) -> 104.66 | K35: Logement
E36: Cotisation Eurocompte | F36: 19.03 | G36: x | H36: =IF(G36="x",F36,0) -> 19.03
E37: Indivision | F37: 33.89 | G37: x | H37: =IF(G37="x",F37,0) -> 33.89
A39: Etat mois précédent | C39: ='Janvier 2026'!D43 -> #REF!
A40: Recettes fixes | C40: =SUM(C2:C6) -> 7187.14 | E40: Somme dépenses prévues | F40: =SUM(F2:F38) -> 4415.1 | G40: Somme dépenses réelles | H40: =SUM(H2:H38) -> 4317.12 | I40: Delta moins les exceptions
A41: Recettes additionnelles du mois | C41: =SUM(C8:C35) -> 296.66 | E41: Reste previsionnel | F41: =C42-F40 -> #REF! | G41: Delta du mois | H41: =C39+C40+C41-H40-F42 -> #REF!
A42: Total Recettes | C42: =SUM(C39:C41) -> #REF! | E42: Somme dépenses non prévues | F42: =SUM(J44:J246) -> 3724.67
A43: Reste prévu | B43: =$C$42-$F$40-$F$42 -> #REF! | C43: Reste réel | D43: =$C$42-$H$40-$F$42 -> #REF!
...

Sheet Janvier 2026
B1: Recettes | E1: Dépenses | K1: Cadeau
B3: Salaire Pierre | C3: 5441.88 | E3: Loyer Elouen | F3: 669.7 | G3: x | H3: =IF(G3="x",F3,0) -> 669.7 | K3: Logement
B4: Salaire Sterenn | C4: 1938.46 | E4: Argent de poche Elouen | F4: 200 | G4: x | H4: =IF(G4="x",F4,0) -> 200 | K4: Charges
B5: CAF | C5: 113.3 | E5: Engie Elouen | F5: 70 | G5: x | H5: =IF(G5="x",F5,0) -> 70 | K5: Charges
E6: Argent de poche Arthur | F6: 164.99 | G6: x | H6: =IF(G6="x",F6,0) -> 164.99 | K6: Charges
E7: Prêt 25 | F7: 995.15 | G7: x | H7: =IF(G7="x",F7,0) -> 995.15 | K7: Logement
B8: CPAM | C8: 21 | E8: Prêt 15 | F8: 883.42 | G8: x | H8: =IF(G8="x",F8,0) -> 883.42 | K8: Logement
B9: Regularisation Engie | C9: 509.85 | E9: Assurances prêt | F9: 11.46 | G9: x | H9: =IF(G9="x",F9,0) -> 11.46 | K9: Logement
B10: Crédit Impots | C10: 449 | E10: Assurances prêt | F10: 32.57 | G10: x | H10: =IF(G10="x",F10,0) -> 32.57 | K10: Logement
B11: Epargne Travaux | C11: 328.24 | E11: Assurances prêt | F11: 84.98 | G11: x | H11: =IF(G11="x",F11,0) -> 84.98 | K11: Logement
B12: Ael Telephone | C12: 576.99 | E12: Assurances prêt | F12: 33.49 | G12: x | H12: =IF(G12="x",F12,0) -> 33.49 | K12: Logement
B13: Ael Coque | C13: 51.59 | E13: Disney | F13: 6.99 | G13: x | H13: =IF(G13="x",F13,0) -> 6.99 | K13: Internet/Téléphone
B14: CPAM | C14: 26.15 | E14: EDF Arthur | F14: 43.96 | G14: x | H14: =IF(G14="x",F14,0) -> 43.96 | K14: Charges
E15: EkWateur | F15: 208 | G15: x | H15: =IF(G15="x",F15,0) -> 208 | K15: Charges
E16: Sosh Maison | F16: 24.99 | G16: x | H16: =IF(G16="x",F16,0) -> 24.99 | K16: Internet/Téléphone
E17: Sosh Arthur | F17: 14.99 | G17: x | H17: =IF(G17="x",F17,0) -> 14.99 | K17: Internet/Téléphone
E18: Sosh Ael | F18: 14.99 | G18: x | H18: =IF(G18="x",F18,0) -> 14.99 | K18: Internet/Téléphone
E19: Sosh Elouen | F19: 14.99 | H19: =IF(G19="x",F19,0) -> 0 | K19: Internet/Téléphone
E20: Sosh Sterenn | F20: 10.99 | G20: x | H20: =IF(G20="x",F20,0) -> 10.99 | K20: Internet/Téléphone
E21: Mutuelle | F21: 102.87 | G21: No prélevé départ Vivinter | H21: =IF(G21="x",F21,0) -> 0 | K21: Assurances/Mutuelle
E22: Mutuelle (Vivinter) | F22: 104.98 | G22: x | H22: =IF(G22="x",F22,0) -> 104.98 | K22: Assurances/Mutuelle
E23: Suravenir Habitation | F23: 53.22 | G23: x | H23: =IF(G23="x",F23,0) -> 53.22 | K23: Assurances/Mutuelle
E24: VW LDD | F24: 331.65 | G24: x | H24: =IF(G24="x",F24,0) -> 331.65 | K24: Voiture/Déplacement
E25: Suravenir Voiture | F25: 94.22 | G25: x | H25: =IF(G25="x",F25,0) -> 94.22 | K25: Assurances/Mutuelle
E26: Suravenir Garanties Vie | F26: 28.58 | G26: x | H26: =IF(G26="x",F26,0) -> 28.58 | K26: Assurances/Mutuelle
E27: Joséphine | F27: 20 | G27: x | H27: =IF(G27="x",F27,0) -> 20 | K27: Divers
E28: Canal Plus | F28: 21.99 | G28: x | H28: =IF(G28="x",F28,0) -> 21.99 | K28: Internet/Téléphone
H29: =IF(G29="x",F29,0) -> 0 | K29: Voiture/Déplacement
E30: Keolis Elouen | F30: 21.4 | G30: x | H30: =IF(G30="x",F30,0) -> 21.4 | K30: Voiture/Déplacement
E31: Apple | F31: 0.99 | G31: x | H31: =IF(G31="x",F31,0) -> 0.99 | K31: Internet/Téléphone
E32: Apple | F32: 16.99 | G32: x | H32: =IF(G32="x",F32,0) -> 16.99 | K32: Internet/Téléphone
E33: St Charles | F33: 178.3 | G33: x | H33: =IF(G33="x",F33,0) -> 178.3 | K33: Scolarité
E34: Ménage | F34: 136 | G34: x | H34: =IF(G34="x",F34,0) -> 136 | K34: Logement
E35: Urssaaf | F35: 52.34 | G35: x | H35: =IF(G35="x",F35,0) -> 52.34 | K35: Logement
E36: Cotisation Eurocompte | F36: 19.03 | G36: x | H36: =IF(G36="x",F36,0) -> 19.03
E37: Indivision | F37: 33.89 | G37: x | H37: =IF(G37="x",F37,0) -> 33.89
A39: Etat mois précédent | C39: =#REF! -> #REF!
A40: Recettes fixes | C40: =SUM(C2:C6) -> 7493.64 | E40: Somme dépenses prévues | F40: =SUM(F2:F38) -> 4702.11 | G40: Somme dépenses réelles | H40: =SUM(H2:H38) -> 4584.25 | I40: Delta moins les exceptions
A41: Recettes additionnelles du mois | C41: =SUM(C8:C35) -> 1962.82 | E41: Reste previsionnel | F41: =C42-F40 -> #REF! | G41: Delta du mois | H41: =C39+C40+C41-H40-F42 -> #REF!
A42: Total Recettes | C42: =SUM(C39:C41) -> #REF! | E42: Somme dépenses non prévues | F42: =SUM(J44:J246) -> 4923.1
...
